Workbook
Name Slicer_Category: #N/A
Name Slicer_Deal_Tag: #N/A

Sheet BigBasket
A1: Product Name | B1: Brand | C1: Brand Count | D1: Price | E1: Discount Price | F1: Discount % | G1: Savings | H1: Deal Tag | I1: Quantity | J1: Category | K1: Sub Category
A2: Onion (Loose) | B2: Fresho | C2: =COUNTIF($B$2:$B$8156,B2) -> 477 | D2: 69.75 | E2: 52 | F2: =IFERROR((D2-E2)/D2,"NA") -> 0.25448029 | G2: =D2-E2 -> 17.75 | H2: =IF(F2>M$4,"Good Deal","Regular") -> Good Deal | I2: 2 kg | J2: Fruits & Vegetables | K2: Potato, Onion & Tomato
A3: Onion | B3: Fresho | C3: =COUNTIF($B$2:$B$8156,B3) -> 477 | D3: 174.35 | E3: 130 | F3: =IFERROR((D3-E3)/D3,"NA") -> 0.25437339 | G3: =D3-E3 -> 44.35 | H3: =IF(F3>M$4,"Good Deal","Regular") -> Good Deal | I3: 5 kg | J3: Fruits & Vegetables | K3: Potato, Onion & Tomato | M3: Deal Tag
A4: Onion (Loose) | B4: Fresho | C4: =COUNTIF($B$2:$B$8156,B4) -> 477 | D4: 34.87 | E4: 26 | F4: =IFERROR((D4-E4)/D4,"NA") -> 0.25437339 | G4: =D4-E4 -> 8.87 | H4: =IF(F4>M$4,"Good Deal","Regular") -> Good Deal | I4: 1 kg | J4: Fruits & Vegetables | K4: Potato, Onion & Tomato | M4: 0.2
A5: Onion | B5: Fresho | C5: =COUNTIF($B$2:$B$8156,B5) -> 477 | D5: 69.74 | E5: 52 | F5: =IFERROR((D5-E5)/D5,"NA") -> 0.25437339 | G5: =D5-E5 -> 17.74 | H5: =IF(F5>M$4,"Good Deal","Regular") -> Good Deal | I5: 2 kg | J5: Fruits & Vegetables | K5: Potato, Onion & Tomato
A6: Onion (Loose) | B6: Fresho | C6: =COUNTIF($B$2:$B$8156,B6) -> 477 | D6: 174.37 | E6: 129 | F6: =IFERROR((D6-E6)/D6,"NA") -> 0.26019384 | G6: =D6-E6 -> 45.37 | H6: =IF(F6>M$4,"Good Deal","Regular") -> Good Deal | I6: 5 kg | J6: Fruits & Vegetables | K6: Potato, Onion & Tomato
A7: Farm Eggs - Table Tray, Medium, Antibiotic Residue-Free | B7: Fresho | C7: =COUNTIF($B$2:$B$8156,B7) -> 477 | D7: 110 | E7: 78 | F7: =IFERROR((D7-E7)/D7,"NA") -> 0.29090909 | G7: =D7-E7 -> 32 | H7: =IF(F7>M$4,"Good Deal","Regular") -> Good Deal | I7: 12 pcs | J7: Eggs, Meat & Fish | K7: Farm Eggs
A8: Farm Eggs - Table Tray, Medium, Antibiotic Residue-Free | B8: Fresho | C8: =COUNTIF($B$2:$B$8156,B8) -> 477 | D8: 210 | E8: 181 | F8: =IFERROR((D8-E8)/D8,"NA") -> 0.13809524 | G8: =D8-E8 -> 29 | H8: =IF(F8>M$4,"Good Deal","Regular") -> Regular | I8: 30 pcs | J8: Eggs, Meat & Fish | K8: Farm Eggs
A9: Potato (Loose) | B9: Fresho | C9: =COUNTIF($B$2:$B$8156,B9) -> 477 | D9: 50.32 | E9: 38.75 | F9: =IFERROR((D9-E9)/D9,"NA") -> 0.22992846 | G9: =D9-E9 -> 11.57 | H9: =IF(F9>M$4,"Good Deal","Regular") -> Good Deal | I9: 1 kg | J9: Fruits & Vegetables | K9: Potato, Onion & Tomato
A10: Potato | B10: Fresho | C10: =COUNTIF($B$2:$B$8156,B10) -> 477 | D10: 100.65 | E10: 77.5 | F10: =IFERROR((D10-E10)/D10,"NA") -> 0.23000497 | G10: =D10-E10 -> 23.15 | H10: =IF(F10>M$4,"Good Deal","Regular") -> Good Deal | I10: 2 kg | J10: Fruits & Vegetables | K10: Potato, Onion & Tomato
A11: Eggs - Regular | B11: Fresho | C11: =COUNTIF($B$2:$B$8156,B11) -> 477 | D11: 250 | E11: 250 | F11: =IFERROR((D11-E11)/D11,"NA") -> 0 | G11: =D11-E11 -> 0 | H11: =IF(F11>M$4,"Good Deal","Regular") -> Regular | I11: 5x6 pcs | J11: Eggs, Meat & Fish | K11: Farm Eggs
A12: Farm Eggs - Regular, Medium, Antibiotic Residue-Free | B12: Fresho | C12: =COUNTIF($B$2:$B$8156,B12) -> 477 | D12: 50 | E12: 38 | F12: =IFERROR((D12-E12)/D12,"NA") -> 0.24 | G12: =D12-E12 -> 12 | H12: =IF(F12>M$4,"Good Deal","Regular") -> Good Deal | I12: 6 pcs | J12: Eggs, Meat & Fish | K12: Farm Eggs
A13: Eggs - Regular | B13: Fresho | C13: =COUNTIF($B$2:$B$8156,B13) -> 477 | D13: 100 | E13: 76 | F13: =IFERROR((D13-E13)/D13,"NA") -> 0.24 | G13: =D13-E13 -> 24 | H13: =IF(F13>M$4,"Good Deal","Regular") -> Good Deal | I13: 2x6 pcs | J13: Eggs, Meat & Fish | K13: Farm Eggs
A14: Eggs - Regular | B14: Fresho | C14: =COUNTIF($B$2:$B$8156,B14) -> 477 | D14: 200 | E14: 200 | F14: =IFERROR((D14-E14)/D14,"NA") -> 0 | G14: =D14-E14 -> 0 | H14: =IF(F14>M$4,"Good Deal","Regular") -> Regular | I14: 4x6 pcs | J14: Eggs, Meat & Fish | K14: Farm Eggs
A15: Atta/Godihittu - Whole Wheat | B15: Aashirvaad | C15: =COUNTIF($B$2:$B$8156,B15) -> 19 | D15: 119 | E15: 118 | F15: =IFERROR((D15-E15)/D15,"NA") -> 0.0084033613 | G15: =D15-E15 -> 1 | H15: =IF(F15>M$4,"Good Deal","Regular") -> Regular | I15: 2 kg | J15: Foodgrains, Oil & Masala | K15: Atta Whole Wheat
A16: Atta/Godihittu - Whole Wheat | B16: Aashirvaad | C16: =COUNTIF($B$2:$B$8156,B16) -> 19 | D16: 301 | E16: 292 | F16: =IFERROR((D16-E16)/D16,"NA") -> 0.029900332 | G16: =D16-E16 -> 9 | H16: =IF(F16>M$4,"Good Deal","Regular") -> Regular | I16: 5 kg | J16: Foodgrains, Oil & Masala | K16: Atta Whole Wheat
... A8156: Blush & Glow - Green Apple Apricot Gel Scrub, Gentle On Skin, Deep Cleansing | B8156: Lakme | C8156: =COUNTIF($B$2:$B$8156,B8156) -> 83 | D8156: 250 | E8156: 175 | F8156: =IFERROR((D8156-E8156)/D8156,"NA") -> 0.3 | G8156: =D8156-E8156 -> 75 | H8156: =IF(F8156>M$4,"Good Deal","Regular") -> Good Deal | I8156: 100 g | J8156: Beauty & Hygiene | K8156: Face Care

Sheet LookUp
A1: Search Product Name: | B1: Potato
A2: Quantity: | B2: 2 kg
A4: Brand | B4: {=_xlfn.XLOOKUP(1, (BigBasket!A2:A8156=B1)*(BigBasket!I2:I8156=B2),BigBasket!B2:B8156,"Not Found")} -> Fresho
A5: Price | B5: {=_xlfn.XLOOKUP(1, (BigBasket!A2:A8156=B1)*(BigBasket!I2:I8156=B2), BigBasket!D2:D8156, "Not Found")} -> 100.65
A6: Discount Price | B6: {=_xlfn.XLOOKUP(1, (BigBasket!A2:A8156=B1)*(BigBasket!I2:I8156=B2), BigBasket!E2:E8156, "Not Found")} -> 77.5
A7: Savings | B7: {=_xlfn.XLOOKUP(1, (BigBasket!A2:A8156=$B$1)*(BigBasket!I2:I8156=$B$2), BigBasket!G2:G8156, "Not Found")} -> 23.15
A8: Discount % | B8: {=_xlfn.XLOOKUP(1, (BigBasket!A2:A8156=$B$1)*(BigBasket!I2:I8156=$B$2), BigBasket!F2:F8156, "Not Found")} -> 0.23000497
A9: Deal Tag | B9: {=_xlfn.XLOOKUP(1, (BigBasket!A2:A8156=$B$1)*(BigBasket!I2:I8156=$B$2), BigBasket!H2:H8156, "Not Found")} -> Good Deal
A10: Category | B10: {=_xlfn.XLOOKUP(1, (BigBasket!A2:A8156=B1)*(BigBasket!I2:I8156=B2), BigBasket!J2:J8156, "Not Found")} -> Fruits & Vegetables
A11: Sub Category | B11: {=_xlfn.XLOOKUP(1, (BigBasket!A2:A8156=$B$1)*(BigBasket!I2:I8156=$B$2), BigBasket!K2:K8156, "Not Found")} -> Potato, Onion & Tomato

Sheet Analysis
A3: Row Labels | B3: Products by Category | D3: Insight:
A4: Beauty & Hygiene | B4: 3745 | D4: • Beauty & Hygiene contains the highest number of products in the dataset.
A5: Kitchen, Garden & Pets | B5: 1316 | D5: • This indicates that BigBasket offers a wide variety of personal care and hygiene products.
A6: Foodgrains, Oil & Masala | B6: 718
A7: Cleaning & Household | B7: 560
A8: Gourmet & World Food | B8: 490
A9: Snacks & Branded Foods | B9: 408
A10: Eggs, Meat & Fish | B10: 358
A11: Bakery, Cakes & Dairy | B11: 169
A12: Beverages | B12: 147
A13: Baby Care | B13: 127
A14: Fruits & Vegetables | B14: 117
A15: Grand Total | B15: 8155
A19: Row Labels | B19: Count of Product Name | D19: Insight:
A20: Fresho | B20: 477 | D20: • Fresho dominates the catalog with the largest product count.
A21: Bb Royal | B21: 410 | D21: • Most products are concentrated among a few major brands.
A22: Bb Home | B22: 183
A23: Healthvit | B23: 98
A24: Dp | B24: 88
A25: Gooddiet | B25: 87
A26: Soulflower | B26: 86
A27: Nivea | B27: 83
A28: Lakme | B28: 83
A29: Biotique | B29: 79
A30: Grand Total | B30: 1674
A34: Row Labels | B34: Average of Discount % by Category | D34: Insight:
A35: Kitchen, Garden & Pets | B35: 0.38103876 | D35: • Kitchen, Garden & Pets has the highest average discount at 38.10%, making it the most heavily discounted category in the dataset.
A36: Fruits & Vegetables | B36: 0.37284982 | D36: • The high discount percentages in these categories suggest that BigBasket uses price reductions to attract customers and increase sales.
A37: Cleaning & Household | B37: 0.36358986
A38: Gourmet & World Food | B38: 0.31930548
A39: Eggs, Meat & Fish | B39: 0.3153946
A40: Beauty & Hygiene | B40: 0.30891868
A41: Foodgrains, Oil & Masala | B41: 0.29776331
A42: Snacks & Branded Foods | B42: 0.26225649
A43: Baby Care | B43: 0.26149785
A44: Bakery, Cakes & Dairy | B44: 0.25772873
A45: Beverages | B45: 0.23350337
A46: Grand Total | B46: 0.31966134
A50: Row Labels | B50: Count of Product Name | D50: Insight:
A51: Good Deal | B51: 7189 | D51: • Good Deal products outnumber Regular products in the dataset.
...

Sheet Dashboard
B1: BigBasket Product Analysis Dashboard
